Workbook

Sheet README
A1: SIMULATEUR KALYPSO — MODE D'EMPLOI
A3: Construit par Jarvis pour la SAE BUT GEA. Le jour J : on remplit les cases marquees [A REMPLIR] et tout se recalcule.
A5: ONGLETS :
A6: 1. Parametres | B6: Toutes les donnees du jeu. Choisis le fournisseur via "Prix retenu".
A7: 2. Production | B7: Entre les quantites a produire -> verifie le goulot MOULAGE (alerte si depassement).
A8: 3. CoutRevient | B8: Cout unitaire calcule de chaque bateau (matieres + heures machine).
A9: 4. Marges | B9: Entre les PRIX DE VENTE (etude Markinform) -> regarde "Marge par HTM moulage".
A10: 5. Resultat | B10: Compte de resultat mensuel. Remplis Publicite et Etudes.
A11: 6. Decisions | B11: Recap a recopier sur la feuille rouge.
A13: REGLE D'OR :
A14: - Le MOULAGE est le goulot. Toute la prod se cale dessus.
A15: - "Marge par HTM moulage" (onglet Marges) = quel bateau privilegier.
A16: - Ne jamais tomber en decouvert (13%/an d'agios).
A18: Modele simplifie (pas de decalage de tresorerie). On l'affine le jour J avec la grille de notation.

Sheet Parametres
A1: PARAMETRES DU JEU KALYPSO
A3: --- MATIERES PREMIERES (prix unitaires) ---
A4: Prix plastique P1 (comptant) EUR/t | B4: 4100
A5: Prix plastique P2 (1 mois) EUR/t | B5: 4200
A6: Prix plastique P3 (2 mois) EUR/t | B6: 4300
A7: Prix bois B1 (comptant) EUR/m3 | B7: 1300
A8: Prix bois B2 (1 mois) EUR/m3 | B8: 1450
A9: Prix bois B3 (2 mois) EUR/m3 | B9: 1600
A11: Prix plastique RETENU (modifiable) EUR/t | B11: 4200 | C11: <-- change selon fournisseur
A12: Prix bois RETENU (modifiable) EUR/m3 | B12: 1450 | C12: <-- change selon fournisseur
A14: --- CONSOMMATION MATIERES / BATEAU ---
B15: Bateau A | C15: Bateau B | D15: Bateau C
A16: Plastique (t) | B16: 0.2 | C16: 0.4 | D16: 1
A17: Bois (m3) | B17: 0.1 | C17: 0.2 | D17: 0.5
A19: --- HEURES MACHINE (HTM) / BATEAU ---
B20: Bateau A | C20: Bateau B | D20: Bateau C
A21: Moulage (HTM) | B21: 8 | C21: 12 | D21: 28
A22: Finition (HTM) | B22: 10 | C22: 14 | D22: 28
A24: --- COUTS HORAIRES & CAPACITE ---
A25: Cout HTM moulage EUR/HTM | B25: 25
A26: Cout HTM finition EUR/HTM | B26: 35
A27: Capacite par robot (HTM/mois) | B27: 200
A28: Nb robots moulage | B28: 4
A29: Nb robots finition | B29: 6
A31: --- COUTS FIXES PRODUCTION ---
A32: Entretien / robot / mois | B32: 2000
A33: Entretien atelier moulage / mois | B33: 4000
A34: Entretien atelier finition / mois | B34: 3000
A35: Valeur d'un robot | B35: 75000
A36: Duree amortissement robot (mois) | B36: 60
A38: --- FORCE DE VENTE ---
A39: Nb representants | B39: 7
A40: Indice representants | B40: 100
A41: Valeur indice 100 (EUR brut/mois) | B41: 1700
A42: Taux commission (% du CA) | B42: 0.08
A44: --- PERSONNEL ADMINISTRATIF ---
A45: Categorie | B45: Effectif | C45: Indice
A46: Direction | B46: 1 | C46: 450
A47: Cadre | B47: 2 | C47: 240
A48: Employe | B48: 5 | C48: 110
...

Sheet Production
A1: PRODUCTION — CAPACITE & GOULOT
A3: [A REMPLIR] Quantites a produire par mois
B4: Bateau A | C4: Bateau B | D4: Bateau C
A5: Quantite a produire | B5: 80 | C5: 0 | D5: 0
A7: CAPACITE DES ATELIERS (HTM/mois)
A8: Capacite moulage | B8: =Parametres!B27*Parametres!B28 -> 800
A9: Capacite finition | B9: =Parametres!B27*Parametres!B29 -> 1200
A11: CONSOMMATION HTM PAR LA PRODUCTION
A12: HTM moulage consommees | B12: =B5*Parametres!B21+C5*Parametres!C21+D5*Parametres!D21 -> 640
A13: HTM finition consommees | B13: =B5*Parametres!B22+C5*Parametres!C22+D5*Parametres!D22 -> 800
A15: TAUX D'UTILISATION
A16: Moulage (goulot) | B16: =IF(B8>0,B12/B8,0) -> 0.8
A17: Finition | B17: =IF(B9>0,B13/B9,0) -> 0.66666667
A19: ALERTE CAPACITE
A20: Moulage | B20: =IF(B12>B8,"DEPASSEMENT MOULAGE",IF(B12=B8,"AU MAX","OK")) -> OK
A21: Finition | B21: =IF(B13>B9,"DEPASSEMENT FINITION",IF(B13=B9,"AU MAX","OK")) -> OK
A23: MAX THEORIQUE SI UN SEUL MODELE (capacite actuelle)
A24: Si 100% A | B24: =INT(MIN(Parametres!B27*Parametres!B28/Parametres!B21,Parametres!B27*Parametres!B29/Parametres!B22)) -> 100
A25: Si 100% B | B25: =INT(MIN(Parametres!B27*Parametres!B28/Parametres!C21,Parametres!B27*Parametres!B29/Parametres!C22)) -> 66
A26: Si 100% C | B26: =INT(MIN(Parametres!B27*Parametres!B28/Parametres!D21,Parametres!B27*Parametres!B29/Parametres!D22)) -> 28

Sheet CoutRevient
A1: COUT DE REVIENT UNITAIRE
A3: Poste | B3: Bateau A | C3: Bateau B | D3: Bateau C
A4: Cout plastique | B4: =Parametres!B16*Parametres!B11 -> 840 | C4: =Parametres!C16*Parametres!B11 -> 1680 | D4: =Parametres!D16*Parametres!B11 -> 4200
A5: Cout bois | B5: =Parametres!B17*Parametres!B12 -> 145 | C5: =Parametres!C17*Parametres!B12 -> 290 | D5: =Parametres!D17*Parametres!B12 -> 725
A6: Cout HTM moulage | B6: =Parametres!B21*Parametres!B25 -> 200 | C6: =Parametres!C21*Parametres!B25 -> 300 | D6: =Parametres!D21*Parametres!B25 -> 700
A7: Cout HTM finition | B7: =Parametres!B22*Parametres!B26 -> 350 | C7: =Parametres!C22*Parametres!B26 -> 490 | D7: =Parametres!D22*Parametres!B26 -> 980
A8: COUT DIRECT UNITAIRE | B8: =SUM(B4:B7) -> 1535 | C8: =SUM(C4:C7) -> 2760 | D8: =SUM(D4:D7) -> 6605
A10: --- Frais fixes production (indicatif) ---
A11: Total fixes prod / mois | B11: =Parametres!B32*(Parametres!B28+Parametres!B29)+Parametres!B33+Parametres!B34+(Parametres!B28+Parametres!B29)*Parametres!B35/Parametres!B36 -> 39500
A12: Total unites produites / mois | B12: =Production!B5+Production!C5+Production!D5 -> 80
A13: Fixe / unite (moyen) | B13: =IF(B12>0,B11/B12,0) -> 493.75
A14: COUT COMPLET INDICATIF / unite | B14: =B8+$B$13 -> 2028.75 | C14: =C8+$B$13 -> 3253.75 | D14: =D8+$B$13 -> 7098.75

Sheet Marges
A1: MARGES & PRIORISATION
A3: [A REMPLIR] Prix de vente HT (etude Markinform "effet prix")
B4: Bateau A | C4: Bateau B | D4: Bateau C
A5: Prix de vente HT | B5: 0 | C5: 0 | D5: 0
A6: Cout direct unitaire | B6: =CoutRevient!B8 -> 1535 | C6: =CoutRevient!C8 -> 2760 | D6: =CoutRevient!D8 -> 6605
A7: Marge unitaire | B7: =B5-B6 -> -1535 | C7: =C5-C6 -> -2760 | D7: =D5-D6 -> -6605
A8: Taux de marge | B8: =IF(B5>0,B7/B5,0) -> 0 | C8: =IF(C5>0,C7/C5,0) -> 0 | D8: =IF(D5>0,D7/D5,0) -> 0
A10: PRIORISATION PAR LE GOULOT (moulage)
A11: HTM moulage / bateau | B11: =Parametres!B21 -> 8 | C11: =Parametres!C21 -> 12 | D11: =Parametres!D21 -> 28
A12: *** Marge par HTM moulage *** | B12: =IF(B11>0,B7/B11,0) -> -191.875 | C12: =IF(C11>0,C7/C11,0) -> -230 | D12: =IF(D11>0,D7/D11,0) -> -235.89286
A14: CONTRIBUTION TOTALE (selon quantites produites)
A15: Quantite produite | B15: =Production!B5 -> 80 | C15: =Production!C5 -> 0 | D15: =Production!D5 -> 0
A16: Marge totale par bateau | B16: =B7*B15 -> -122800 | C16: =C7*C15 -> 0 | D16: =D7*D15 -> 0
A17: MARGE TOTALE GLOBALE | B17: =SUM(B16:D16) -> -122800

Sheet Resultat
A1: COMPTE DE RESULTAT MENSUEL (simplifie)
A3: PRODUITS
A4: Chiffre d'affaires (CA) | B4: =Marges!B5*Production!B5+Marges!C5*Production!C5+Marges!D5*Production!D5 -> 0
A6: CHARGES
A7: Achats matieres consommees | B7: =(Production!B5*Parametres!B16+Production!C5*Parametres!C16+Production!D5*Parametres!D16)*Parametres!B11+(Production!B5*Parametres!B17+Production!C5*Parametres!C17+Production!D5*Parametres!D17)*Parametres!B12 -> 78800
A8: Cout HTM (moulage+finition) | B8: =Production!B12*Parametres!B25+Production!B13*Parametres!B26 -> 44000
A9: Couts fixes production | B9: =CoutRevient!B11 -> 39500
A10: Salaires representants | B10: =Parametres!B39*Parametres!B40/100*Parametres!B41 -> 11900
A11: Commissions sur ventes | B11: =Parametres!B42*B4 -> 0
A12: Salaires administratifs | B12: =(Parametres!B46*Parametres!C46+Parametres!B47*Parametres!C47+Parametres!B48*Parametres!C48)/100*Parametres!B41 -> 25160
A13: (sous-total masse salariale)
A14: Charges sociales (40%) | B14: =Parametres!B58*(B10+B12) -> 14824
A15: Impots/taxes salaires (5%) | B15: =Parametres!B59*(B10+B12) -> 1853
A16: [A REMPLIR] Publicite (marque + specifique) | B16: 12000
A17: [A REMPLIR] Etudes Markinform | B17: 0
A18: Charges subies | B18: =Parametres!B52+Parametres!B53+Parametres!B54+Parametres!B55+(Parametres!C52+Parametres!C53+Parametres!C54+Parametres!C55)*B4 -> 30500
A19: Creances impayees | B19: =Parametres!B60*B4 -> 0
A20: TOTAL CHARGES | B20: =SUM(B7:B19) -> 258537
A22: RESULTAT AVANT IS | B22: =B4-B20 -> -258537
A23: IS (25% si benefice) | B23: =IF(B22>0,Parametres!B61*B22,0) -> 0
A24: RESULTAT NET MENSUEL | B24: =B22-B23 -> -258537
A26: Resultat net trimestriel (x3, indicatif) | B26: =B24*3 -> -775611

Sheet Decisions
A1: FEUILLE DE DECISIONS — RECAP (a reporter au stylo rouge)
A3: APPROVISIONNEMENT
A4: Fournisseur plastique retenu | B4: P2
A5: Quantite plastique commandee /mois (t) | B5: 0
A6: Fournisseur bois retenu | B6: B2
A7: Quantite bois commandee /mois (m3) | B7: 0
A9: PRODUCTION
A10: Bateau A a produire | B10: =Production!B5 -> 80
A11: Bateau B a produire | B11: =Production!C5 -> 0
A12: Bateau C a produire | B12: =Production!D5 -> 0
A13: Achat(+)/cession(-) robots moulage | B13: 0
A14: Achat(+)/cession(-) robots finition | B14: 0
A16: MARKETING
A17: Prix vente A | B17: =Marges!B5 -> 0
A18: Prix vente B | B18: =Marges!C5 -> 0
A19: Prix vente C | B19: =Marges!D5 -> 0
A20: Budget pub de marque /mois | B20: 12000
A21: Axe com principal | B21: (prix / confort / resistance / esthetique)
A22: Axe com secondaire | B22: (prix / confort / resistance / esthetique)
A23: Pub specifique A / B / C | B23: 0 | C23: 0 | D23: 0
A24: Delai paiement client | B24: (comptant / 30j / 60j / 90j)
A25: Force de vente: embauche(+)/licenciement(-) | B25: 0
A27: ETUDES MARKINFORM COMMANDEES
A28: (lister les n. : prevision ventes / effet prix / effet pub...)
A30: FINANCE
A31: Emprunt / placement / decouvert | B31: (a preciser)
